<?xml version="1.0" ?>
<!-- =================================================================================== -->
<!-- |    This document was autogenerated by xacro from new_bcr_robot.xacro            | -->
<!-- |    EDITING THIS FILE BY HAND IS NOT RECOMMENDED                                 | -->
<!-- =================================================================================== -->
<robot name="new_bcr_robot">
  <!--................................ XACRO CONSTANTS .............................. -->
  <!-- ............................... LOAD MACROS ................................. -->
  <material name="black">
    <color rgba="0.0 0.0 0.0 1.0"/>
  </material>
  <material name="blue">
    <color rgba="0.0 0.0 0.8 1.0"/>
  </material>
  <material name="green">
    <color rgba="0.0 0.8 0.0 1.0"/>
  </material>
  <material name="yellow">
    <color rgba="1.0 1.0 0.0 1.0"/>
  </material>
  <material name="dark_grey">
    <color rgba="0.2 0.2 0.2 1.0"/>
  </material>
  <material name="orange">
    <color rgba="1.0 0.4235294117647059 0.0392156862745098 1.0"/>
  </material>
  <material name="brown">
    <color rgba="0.5450980392156862 0.27058823529411763 0.07450980392156863 1.0"/>
  </material>
  <material name="red">
    <color rgba="0.8 0.0 0.0 1.0"/>
  </material>
  <material name="turquoise">
    <color rgba="0.25098039215686274 0.8784313725490196 0.8156862745098039 1.0"/>
  </material>
  <material name="purple">
    <color rgba="0.5019607843137255 0.0 0.5019607843137255 1.0"/>
  </material>
  <material name="white">
    <color rgba="1.0 1.0 1.0 1.0"/>
  </material>
  <material name="aluminium">
    <color rgba="0.5 0.5 0.5 1"/>
  </material>
  <material name="plastic">
    <color rgba="0.1 0.1 0.1 1"/>
  </material>
  <!--................................ INERTIA MATRICES .............................. -->
  <!-- ............................... TROLLEY WHEEL DEFINITION .............................. -->
  <gazebo>
    <static>false</static>
  </gazebo>
  <gazebo reference="back_left_wheel_joint">
    <mu1 value="0.0"/>
    <mu2 value="0.0"/>
    <kp value="10000000.0"/>
    <kd value="1.0"/>
    <fdir1 value="1 0 0"/>
  </gazebo>
  <gazebo reference="back_right_wheel_joint">
    <mu1 value="0.0"/>
    <mu2 value="0.0"/>
    <kp value="10000000.0"/>
    <kd value="1.0"/>
    <fdir1 value="1 0 0"/>
  </gazebo>
  <gazebo reference="front_left_wheel_joint">
    <mu1 value="0.0"/>
    <mu2 value="0.0"/>
    <kp value="10000000.0"/>
    <kd value="1.0"/>
    <fdir1 value="1 0 0"/>
  </gazebo>
  <gazebo reference="front_right_wheel_joint">
    <mu1 value="0.0"/>
    <mu2 value="0.0"/>
    <kp value="10000000.0"/>
    <kd value="1.0"/>
    <fdir1 value="1 0 0"/>
  </gazebo>
  <gazebo reference="middle_left_wheel_joint">
    <mu1 value="5.0"/>
    <mu2 value="5.0"/>
    <kp value="10000000.0"/>
    <kd value="1.0"/>
    <fdir1 value="1 0 0"/>
  </gazebo>
  <gazebo reference="middle_right_wheel_joint">
    <mu1 value="5.0"/>
    <mu2 value="5.0"/>
    <kp value="10000000.0"/>
    <kd value="1.0"/>
    <fdir1 value="1 0 0"/>
  </gazebo>
  <!-- .....................MULTI WHEEL DIFF DRIVE ................................... -->
  <gazebo>
    <plugin filename="libgazebo_ros_diff_drive.so" name="diffdrive_plugin_multiwheel_middle">
      <robotNamespace/>
      <legacyMode>false</legacyMode>
      <updateRate>100.0</updateRate>
      <leftJoint>middle_left_wheel_joint</leftJoint>
      <rightJoint>middle_right_wheel_joint</rightJoint>
      <wheelSeparation>0.8</wheelSeparation>
      <wheelDiameter>0.2</wheelDiameter>
      <robotBaseFrame>base_link</robotBaseFrame>
      <wheelTorque>20000</wheelTorque>
      <commandTopic>/cmd_vel</commandTopic>
      <odometryTopic>odom</odometryTopic>
      <odometryFrame>odom</odometryFrame>
      <publishOdometryTf>true</publishOdometryTf>
      <publishOdometryMsg>true</publishOdometryMsg>
      <wheelAcceleration>5.0</wheelAcceleration>
    </plugin>
  </gazebo>
  <!--............................... IMU PLUGIN ..................................... -->
  <gazebo>
    <plugin filename="libgazebo_ros_imu.so" name="imu_plugin">
      <updateRate>50.0</updateRate>
      <bodyName>base_link</bodyName>
      <topicName>/imu</topicName>
      <serviceName>/imu/calibrate</serviceName>
      <accelOffset>0.0 0.0 0.0</accelOffset>
      <accelDrift>0.0 0.0 0.0</accelDrift>
      <accelDriftFrequency>0.0 0.0 0.0</accelDriftFrequency>
      <accelGaussianNoise>0.0 0.0 0.0</accelGaussianNoise>
      <rateOffset>0.0 0.0 0.0</rateOffset>
      <rateDrift>0.0 0.0 0.0</rateDrift>
      <rateDriftFrequency>0.0 0.0 0.0</rateDriftFrequency>
      <rateGaussianNoise>0.0 0.0 0.0</rateGaussianNoise>
      <headingOffset>0.0</headingOffset>
      <headingDrift>0.0</headingDrift>
      <headingDriftFrequency>0.0</headingDriftFrequency>
      <headingGaussianNoise>0.0</headingGaussianNoise>
      <rpyOffset>0.0 0.0 0.0</rpyOffset>
      <xyzOffset>0.0 0.0 0.0</xyzOffset>
      <gaussianNoise>0.0</gaussianNoise>
      <frameName>imu_frame</frameName>
    </plugin>
  </gazebo>
  <!-- ........................... 2D LIDAR PLUGIN ................................... -->
  <!--................................................................................. -->
  <!-- ................................ BASE LINK .................................. -->
  <link name="base_ref"/>
  <link name="base_link">
    <collision>
      <origin rpy="0 0 0" xyz="0 0 0.625"/>
      <geometry>
        <box size="0.95 0.64 0.25"/>
      </geometry>
    </collision>
    <visual>
      <origin rpy="0 0 0" xyz="0 0 0.5"/>
      <geometry>
        <box size="0.95 0.64 0.25"/>
      </geometry>
    </visual>
    <inertial>
      <mass value="7"/>
      <inertia ixx="0.27539166666666665" ixy="0" ixz="0" iyy="0.5629166666666666" iyz="0" izz="0.5629166666666666"/>
    </inertial>
  </link>
  <joint name="base_joint" type="fixed">
    <parent link="base_ref"/>
    <child link="base_link"/>
    <origin rpy="0 0 0.0" xyz="0.0 0 0.0"/>
  </joint>
  <!-- ................................ WHEELS ..................................... -->
  <link name="front_left_wheel">
    <collision>
      <origin rpy="0 1.5707963267948966 1.5707963267948966" xyz="0 0 0"/>
      <geometry>
        <sphere radius="0.06"/>
      </geometry>
    </collision>
    <visual>
      <origin rpy="0 1.5707963267948966 1.5707963267948966" xyz="0 0 0"/>
      <geometry>
        <sphere radius="0.06"/>
      </geometry>
      <material name="black"/>
    </visual>
    <inertial>
      <origin rpy="0 0 0" xyz="0 0 0"/>
      <mass value="0.1"/>
      <inertia ixx="0.00014399999999999998" ixy="0" ixz="0" iyy="0.00014399999999999998" iyz="0" izz="0.00014399999999999998"/>
    </inertial>
    <mu>0.0</mu>
  </link>
  <joint name="front_left_wheel_joint" type="fixed">
    <parent link="base_link"/>
    <child link="front_left_wheel"/>
    <origin rpy="0 0 0" xyz="0.475 0.27 0.06"/>
    <axis rpy="0 0 0" xyz="0 1 0"/>
  </joint>
  <gazebo reference="front_left_wheel">
    <material>Gazebo/Black</material>
  </gazebo>
  <link name="front_right_wheel">
    <collision>
      <origin rpy="0 1.5707963267948966 1.5707963267948966" xyz="0 0 0"/>
      <geometry>
        <sphere radius="0.06"/>
      </geometry>
    </collision>
    <visual>
      <origin rpy="0 1.5707963267948966 1.5707963267948966" xyz="0 0 0"/>
      <geometry>
        <sphere radius="0.06"/>
      </geometry>
      <material name="black"/>
    </visual>
    <inertial>
      <origin rpy="0 0 0" xyz="0 0 0"/>
      <mass value="0.1"/>
      <inertia ixx="0.00014399999999999998" ixy="0" ixz="0" iyy="0.00014399999999999998" iyz="0" izz="0.00014399999999999998"/>
    </inertial>
    <mu>0.0</mu>
  </link>
  <joint name="front_right_wheel_joint" type="fixed">
    <parent link="base_link"/>
    <child link="front_right_wheel"/>
    <origin rpy="0 0 0" xyz="0.475 -0.27 0.06"/>
    <axis rpy="0 0 0" xyz="0 1 0"/>
  </joint>
  <gazebo reference="front_right_wheel">
    <material>Gazebo/Black</material>
  </gazebo>
  <link name="back_left_wheel">
    <collision>
      <origin rpy="0 1.5707963267948966 1.5707963267948966" xyz="0 0 0"/>
      <geometry>
        <sphere radius="0.06"/>
      </geometry>
    </collision>
    <visual>
      <origin rpy="0 1.5707963267948966 1.5707963267948966" xyz="0 0 0"/>
      <geometry>
        <sphere radius="0.06"/>
      </geometry>
      <material name="black"/>
    </visual>
    <inertial>
      <origin rpy="0 0 0" xyz="0 0 0"/>
      <mass value="0.1"/>
      <inertia ixx="0.00014399999999999998" ixy="0" ixz="0" iyy="0.00014399999999999998" iyz="0" izz="0.00014399999999999998"/>
    </inertial>
    <mu>0.0</mu>
  </link>
  <joint name="back_left_wheel_joint" type="fixed">
    <parent link="base_link"/>
    <child link="back_left_wheel"/>
    <origin rpy="0 0 0" xyz="-0.475 0.27 0.06"/>
    <axis rpy="0 0 0" xyz="0 1 0"/>
  </joint>
  <gazebo reference="back_left_wheel">
    <material>Gazebo/Black</material>
  </gazebo>
  <link name="back_right_wheel">
    <collision>
      <origin rpy="0 1.5707963267948966 1.5707963267948966" xyz="0 0 0"/>
      <geometry>
        <sphere radius="0.06"/>
      </geometry>
    </collision>
    <visual>
      <origin rpy="0 1.5707963267948966 1.5707963267948966" xyz="0 0 0"/>
      <geometry>
        <sphere radius="0.06"/>
      </geometry>
      <material name="black"/>
    </visual>
    <inertial>
      <origin rpy="0 0 0" xyz="0 0 0"/>
      <mass value="0.1"/>
      <inertia ixx="0.00014399999999999998" ixy="0" ixz="0" iyy="0.00014399999999999998" iyz="0" izz="0.00014399999999999998"/>
    </inertial>
    <mu>0.0</mu>
  </link>
  <joint name="back_right_wheel_joint" type="fixed">
    <parent link="base_link"/>
    <child link="back_right_wheel"/>
    <origin rpy="0 0 0" xyz="-0.475 -0.27 0.06"/>
    <axis rpy="0 0 0" xyz="0 1 0"/>
  </joint>
  <gazebo reference="back_right_wheel">
    <material>Gazebo/Black</material>
  </gazebo>
  <link name="middle_left_wheel">
    <collision>
      <origin rpy="0 1.5707963267948966 1.5707963267948966" xyz="0 0 0"/>
      <geometry>
        <cylinder length="0.05" radius="0.1"/>
      </geometry>
    </collision>
    <visual>
      <origin rpy="0 1.5707963267948966 1.5707963267948966" xyz="0 0 0"/>
      <geometry>
        <cylinder length="0.05" radius="0.1"/>
      </geometry>
      <material name="black"/>
    </visual>
    <inertial>
      <origin rpy="0 1.5707963267948966 1.5707963267948966" xyz="0 0 0"/>
      <mass value="1"/>
      <inertia ixx="0.002708333333333334" ixy="0" ixz="0" iyy="0.002708333333333334" iyz="0" izz="0.005000000000000001"/>
    </inertial>
    <mu>5.0</mu>
  </link>
  <joint name="middle_left_wheel_joint" type="continuous">
    <parent link="base_link"/>
    <child link="middle_left_wheel"/>
    <origin rpy="0 0 0" xyz="0 0.4 0.1"/>
    <axis rpy="0 0 0" xyz="0 1 0"/>
  </joint>
  <gazebo reference="middle_left_wheel">
    <material>Gazebo/Black</material>
  </gazebo>
  <link name="middle_right_wheel">
    <collision>
      <origin rpy="0 1.5707963267948966 1.5707963267948966" xyz="0 0 0"/>
      <geometry>
        <cylinder length="0.05" radius="0.1"/>
      </geometry>
    </collision>
    <visual>
      <origin rpy="0 1.5707963267948966 1.5707963267948966" xyz="0 0 0"/>
      <geometry>
        <cylinder length="0.05" radius="0.1"/>
      </geometry>
      <material name="black"/>
    </visual>
    <inertial>
      <origin rpy="0 1.5707963267948966 1.5707963267948966" xyz="0 0 0"/>
      <mass value="1"/>
      <inertia ixx="0.002708333333333334" ixy="0" ixz="0" iyy="0.002708333333333334" iyz="0" izz="0.005000000000000001"/>
    </inertial>
    <mu>5.0</mu>
  </link>
  <joint name="middle_right_wheel_joint" type="continuous">
    <parent link="base_link"/>
    <child link="middle_right_wheel"/>
    <origin rpy="0 0 0" xyz="0 -0.4 0.1"/>
    <axis rpy="0 0 0" xyz="0 1 0"/>
  </joint>
  <gazebo reference="middle_right_wheel">
    <material>Gazebo/Black</material>
  </gazebo>
  <!-- ............................. 2D LIDAR ........................................ -->
</robot>
